Workbook

Sheet RawData
A1: Year | B1: Month | C1: Month_Num | D1: Revenue_Consulting | E1: Revenue_ManagedServices | F1: Cost_Personnel | G1: Cost_Operations | H1: Cost_Other | I1: Budget_RevConsulting | J1: Budget_RevMS | K1: Budget_CostPersonnel | L1: Budget_CostOps | M1: Budget_CostOther
A2: 2022 | B2: Jan | C2: 1 | D2: 100800 | E2: 35000 | F2: 81900 | G2: 10100 | H2: 5000 | I2: 139200 | J2: 48300 | K2: 113100 | L2: 13900 | M2: 7000
A3: 2022 | B3: Feb | C3: 2 | D3: 109200 | E3: 35000 | F3: 88700 | G3: 10900 | H3: 5500 | I3: 150800 | J3: 48300 | K3: 122500 | L3: 15100 | M3: 7500
A4: 2022 | B4: Mar | C4: 3 | D4: 126000 | E4: 35000 | F4: 102400 | G4: 12600 | H4: 6300 | I4: 174000 | J4: 48300 | K4: 141400 | L4: 17400 | M4: 8700
A5: 2022 | B5: Apr | C5: 4 | D5: 151200 | E5: 35000 | F5: 122800 | G5: 15100 | H5: 7600 | I5: 208800 | J5: 48300 | K5: 169600 | L5: 20900 | M5: 10400
A6: 2022 | B6: May | C6: 5 | D6: 159600 | E6: 35000 | F6: 129700 | G6: 16000 | H6: 8000 | I6: 220400 | J6: 48300 | K6: 179100 | L6: 22000 | M6: 11000
A7: 2022 | B7: Jun | C7: 6 | D7: 159600 | E7: 35000 | F7: 129700 | G7: 16000 | H7: 8000 | I7: 220400 | J7: 48300 | K7: 179100 | L7: 22000 | M7: 11000
A8: 2022 | B8: Jul | C8: 7 | D8: 159600 | E8: 35000 | F8: 129700 | G8: 16000 | H8: 8000 | I8: 220400 | J8: 48300 | K8: 179100 | L8: 22000 | M8: 11000
A9: 2022 | B9: Aug | C9: 8 | D9: 151200 | E9: 35000 | F9: 122800 | G9: 15100 | H9: 7600 | I9: 208800 | J9: 48300 | K9: 169600 | L9: 20900 | M9: 10400
A10: 2022 | B10: Sep | C10: 9 | D10: 142800 | E10: 35000 | F10: 116000 | G10: 14300 | H10: 7100 | I10: 197200 | J10: 48300 | K10: 160200 | L10: 19700 | M10: 9900
A11: 2022 | B11: Oct | C11: 10 | D11: 142800 | E11: 35000 | F11: 116000 | G11: 14300 | H11: 7100 | I11: 197200 | J11: 48300 | K11: 160200 | L11: 19700 | M11: 9900
A12: 2022 | B12: Nov | C12: 11 | D12: 134400 | E12: 35000 | F12: 109200 | G12: 13400 | H12: 6700 | I12: 185600 | J12: 48300 | K12: 150800 | L12: 18600 | M12: 9300
A13: 2022 | B13: Dec | C13: 12 | D13: 134400 | E13: 35000 | F13: 109200 | G13: 13400 | H13: 6700 | I13: 185600 | J13: 48300 | K13: 150800 | L13: 18600 | M13: 9300
... A37: 2024 | B37: Dec | C37: 12 | D37: 169600 | E37: 44200 | F37: 137800 | G37: 17000 | H37: 8500 | I37: 185600 | J37: 48300 | K37: 150800 | L37: 18600 | M37: 9300
A39: Source: NovaTech Consulting Lda. — Internal Financial Data (Fictitious)

Sheet YoY Bridge
A1: NovaTech — YoY Revenue Bridge 2022 → 2023 (Wednesday) | 2023 → 2024 (Friday)
A2: Bridge = Opening + Volume effect + Rate effect + Mix effect = Closing. Each component explains ONE cause.
A4: Component | B4: € Amount | C4: % of Opening Rev | D4: Formula | E4: Explanation
A5: REVENUE BRIDGE: 2022 → 2023
A6: Opening Revenue 2022 | B6: =SUM(RawData!D2:E13) -> 2091600 | D6: historical total | E6: Starting point — 2022 actual revenue
A7: Volume effect | B7: 240000 | C7: =B7/B6 -> 0.11474469 | D7: (HC23−HC22) × Rate22 × 12 | E7: (47−42) × €4,000 × 12 = +€240,000 More people at same rate))
A8: Rate effect | B8: 169200 | C8: =B8/B6 -> 0.080895009 | D8: HC23 × (Rate23−Rate22) × 12 | E8: 47 × €300 × 12 = +€169,200 Same people, higher billing rate
A9: Mix effect | B9: 0 | C9: 0 | D9: 0 (stable mix) | E9: MS stayed at ~20% of total — no mix shift
A10: Closing Revenue 2023 | B10: =SUM(RawData!D14:E25) -> 2390400 | D10: opening + all effects | E10: Actual: €2,390,400 | Bridge: €2,500,800 ⚠ Gap of €-110,400 = rounding in rate assumption
A12: REVENUE BRIDGE: 2023 → 2024
A14: Component | B14: € Amount | C14: % of Opening Rev | D14: Formula | E14: Explanation
A15: REVENUE BRIDGE: 2023 → 2024
A16: Opening Revenue 2023 | B16: =SUM(RawData!D14:E25) -> 2390400 | D16: historical total | E16: Starting point — 2022 actual revenue
A17: Volume effect | B17: 258000 | C17: =B17/B16 -> 0.10793173 | D17: (HC24−HC23) × Rate23 × 12 | E17: (52−47) × €4,300 × 12 = +€258,000 More people at same rate))
A18: Rate effect | B18: 187200 | C18: =B18/B16 -> 0.078313253 | D18: HC24 × (Rate24−Rate23) × 12 | E18: 52 × €300 × 12 = +€187,200 Same people, higher billing rate
A19: Mix effect | B19: 0 | C19: 0 | D19: 0 (stable mix) | E19: MS stayed at ~20% of total — no mix shift
A20: Closing Revenue 2024 | B20: =SUM(RawData!D26:E37) -> 2639800 | D20: opening + all effects | E20: Actual: €2,639,800 | Bridge: €2,835,600 ⚠ Gap of €-195,800 = rounding in rate assumption
A23: EBITDA SUMMARY
A24: Year | B24: Revenue | C24: Total Costs | D24: EBITDA | E24: EBITDA Margin %
A25: 2022 | B25: =B6 -> 2091600 | C25: =SUM(RawData!F2:H13) -> 1608900 | D25: =B25-C25 -> 482700 | E25: =D25/B25 -> 0.23078026
A26: 2023 | B26: =B10 -> 2390400 | C26: =SUM(RawData!F14:H25) -> 1838700 | D26: =B26-C26 -> 551700 | E26: =D26/B26 -> 0.23079819
A27: 2024 | B27: =B20 -> 2639800 | C27: =SUM(RawData!F26:H37) -> 2030300 | D27: =B27-C27 -> 609500 | E27: =D27/B27 -> 0.2308887

Sheet Drivers
A1: NovaTech Consulting Lda. — Business Drivers (Input Sheet)
A2: YELLOW = assumption | BLUE text = formula (calculated) | Change yellow cells to model scenarios
A4: HEADCOUNT (FTE) — monthly
A5: Year | B5: Jan | C5: Feb | D5: Mar | E5: Apr | F5: May | G5: Jun | H5: Jul | I5: Aug | J5: Sep | K5: Oct | L5: Nov | M5: Dec | N5: AVG | O5: Assumption note
A6: 2022 | B6: 41 | C6: 41 | D6: 41 | E6: 42 | F6: 42 | G6: 42 | H6: 42 | I6: 42 | J6: 42 | K6: 43 | L6: 43 | M6: 43 | N6: =AVERAGE(B6:M6) -> 42 | O6: ASSUMPTION — 42 FTEs year-end 2022. Monthly values estimated with slight ramp.
A7: 2023 | B7: 46 | C7: 46 | D7: 46 | E7: 46 | F7: 47 | G7: 47 | H7: 47 | I7: 47 | J7: 48 | K7: 48 | L7: 48 | M7: 48 | N7: =AVERAGE(B7:M7) -> 47 | O7: ASSUMPTION — 47 FTEs year-end 2023. +5 FTEs vs 2022.
A8: 2024 | B8: 51 | C8: 51 | D8: 51 | E8: 52 | F8: 52 | G8: 52 | H8: 52 | I8: 52 | J8: 52 | K8: 53 | L8: 53 | M8: 53 | N8: =AVERAGE(B8:M8) -> 52 | O8: ASSUMPTION — 52 FTEs year-end 2024. +5 FTEs vs 2023. Change this to model scenarios.
A10: BILLING RATE (€/head/month) — consulting only
A11: Year | B11: Jan | C11: Feb | D11: Mar | E11: Apr | F11: May | G11: Jun | H11: Jul | I11: Aug | J11: Sep | K11: Oct | L11: Nov | M11: Dec | N11: AVG Rate | O11: Assumption note
A12: 2022 | B12: 4000 | C12: 4000 | D12: 4000 | E12: 4000 | F12: 4000 | G12: 4000 | H12: 4000 | I12: 4000 | J12: 4000 | K12: 4000 | L12: 4000 | M12: 4000 | N12: =AVERAGE(B12:M12) -> 4000 | O12: ASSUMPTION — €4,000/month derived from: €1,671,600 ÷ 42 HC ÷ 12 = €3,317. Rounded up to reflect blended rate incl. MS.
A13: 2023 | B13: 4300 | C13: 4300 | D13: 4300 | E13: 4300 | F13: 4300 | G13: 4300 | H13: 4300 | I13: 4300 | J13: 4300 | K13: 4300 | L13: 4300 | M13: 4300 | N13: =AVERAGE(B13:M13) -> 4300 | O13: ASSUMPTION — €4,300/month. €1,910,400 ÷ 47 ÷ 12 = €3,388. Rate increase reflects mix improvement.
A14: 2024 | B14: 4600 | C14: 4600 | D14: 4600 | E14: 4600 | F14: 4600 | G14: 4600 | H14: 4600 | I14: 4600 | J14: 4600 | K14: 4600 | L14: 4600 | M14: 4600 | N14: =AVERAGE(B14:M14) -> 4600 | O14: ASSUMPTION — €4,600/month. €2,109,400 ÷ 52 ÷ 12 = €3,380.
A16: MANAGED SERVICES REVENUE (flat — recurring contracts)
A17: 2022 | B17: 35000 | C17: 35000 | D17: 35000 | E17: 35000 | F17: 35000 | G17: 35000 | H17: 35000 | I17: 35000 | J17: 35000 | K17: 35000 | L17: 35000 | M17: 35000 | N17: =SUM(B17:M17) -> 420000 | O17: ASSUMPTION — €420,000/year ÷ 12 = €35,000/month flat. Recurring contracts.
A18: 2023 | B18: 40000 | C18: 40000 | D18: 40000 | E18: 40000 | F18: 40000 | G18: 40000 | H18: 40000 | I18: 40000 | J18: 40000 | K18: 40000 | L18: 40000 | M18: 40000 | N18: =SUM(B18:M18) -> 480000 | O18: ASSUMPTION — €480,000/year ÷ 12 = €40,000/month flat. Recurring contracts.
A19: 2024 | B19: 44200 | C19: 44200 | D19: 44200 | E19: 44200 | F19: 44200 | G19: 44200 | H19: 44200 | I19: 44200 | J19: 44200 | K19: 44200 | L19: 44200 | M19: 44200 | N19: =SUM(B19:M19) -> 530400 | O19: ASSUMPTION — €530,000/year ÷ 12 = €44,200/month flat. Recurring contracts.
A21: COST PER HEAD SUMMARY (derived — do not edit)
A22: Year | B22: Total Personnel Cost | C22: Avg HC | D22: Cost/Head/Year | E22: Cost/Head/Month | F22: Note
A23: 2022 | B23: =SUMIF(RawData!A:A,"=2022",RawData!F:F) -> 1358100 | C23: =N6 -> 42 | D23: =B23/C23 -> 32335.714 | E23: =D23/12 -> 2694.6429 | F23: DERIVED from RawData — not an assumption
A24: 2023 | B24: =SUMIF(RawData!A:A,"=2023",RawData!F:F) -> 1552200 | C24: =N7 -> 47 | D24: =B24/C24 -> 33025.532 | E24: =D24/12 -> 2752.1277 | F24: DERIVED from RawData — not an assumption
A25: 2024 | B25: =SUMIF(RawData!A:A,"=2024",RawData!F:F) -> 1713800 | C25: =N8 -> 52 | D25: =B25/C25 -> 32957.692 | E25: =D25/12 -> 2746.4744 | F25: DERIVED from RawData — not an assumption

Sheet Variance
A1: NovaTech Consulting Lda. — Variance Analysis:Budget 2025 vs Actuals
A2: Actuals = 2024 data (proxy) | Budget = 2025 targets from RawData | Variance = Actual - Budget
A4: Category | B4: Jan | C4: Fev | D4: Mar | E4: Apr | F4: May | G4: Jun | H4: Jul | I4: Aug | J4: Sep | K4: Oct | L4: Nov | M4: Dec | N4: TOTAL | O4: Var € Total | P4: Var % Total | Q4: Comments
A5: Revenue
A6: Consulting Fees | B6: =RawData!D26-RawData!I26 -> -12000 | C6: =RawData!D27-RawData!I27 -> -13000 | D6: =RawData!D28-RawData!I28 -> -15000 | E6: =RawData!D29-RawData!I29 -> -18000 | F6: =RawData!D30-RawData!I30 -> -19000 | G6: =RawData!D31-RawData!I31 -> -19000 | H6: =RawData!D32-RawData!I32 -> -19000 | I6: =RawData!D33-RawData!I33 -> -18000 | J6: =RawData!D34-RawData!I34 -> -17000 | K6: =RawData!D35-RawData!I35 -> -17000 | L6: =RawData!D36-RawData!I36 -> -16000 | M6: =RawData!D37-RawData!I37 -> -16000 | N6: =SUM(B6:M6) -> -199000 | O6: =SUMIF(RawData!A:A,"=2024",RawData!D:D)-SUMIF(RawData!A:A,"=2024",RawData!I:I) -> -199000 | P6: =IF(SUMIF(RawData!A:A,"=2024",RawData!I:I)=0,0,O6/SUMIF(RawData!A:A,"=2024",RawData!I:I)) -> -0.086206897 | Q6: "Abaixo do budget em 8.6% — shortfall consistente em todos os meses sugere problema de volume (menos FTEs que planeado) ou billing rate abaixo do assumido. Não é problema sazonal."
A7: Managed Services | B7: =RawData!E26-RawData!J26 -> -4100 | C7: =RawData!$E27-RawData!$J27 -> -4100 | D7: =RawData!$E28-RawData!$J28 -> -4100 | E7: =RawData!$E29-RawData!$J29 -> -4100 | F7: =RawData!$E30-RawData!$J30 -> -4100 | G7: =RawData!$E31-RawData!$J31 -> -4100 | H7: =RawData!$E32-RawData!$J32 -> -4100 | I7: =RawData!$E33-RawData!$J33 -> -4100 | J7: =RawData!$E34-RawData!$J34 -> -4100 | K7: =RawData!$E35-RawData!$J35 -> -4100 | L7: =RawData!$E36-RawData!$J36 -> -4100 | M7: =RawData!$E37-RawData!$J37 -> -4100 | N7: =SUM(B7:M7) -> -49200 | O7: =SUMIF(RawData!A:A,"=2024",RawData!E:E)-SUMIF(RawData!A:A,"=2024",RawData!J:J) -> -49200 | P7: =IF(SUMIF(RawData!A:A,"=2024",RawData!J:J)=0,0,O7/SUMIF(RawData!A:A,"=2024",RawData!J:J)) -> -0.084886128 | Q7: Abaixo do budget em 8.6%. MS é receita recorrente flat — variância negativa uniforme indica contratos renovados abaixo do valor orçamentado para 2025."
A8: Total Revenue | B8: =B6+B7 -> -16100 | C8: =C6+C7 -> -17100 | D8: =D6+D7 -> -19100 | E8: =E6+E7 -> -22100 | F8: =F6+F7 -> -23100 | G8: =G6+G7 -> -23100 | H8: =H6+H7 -> -23100 | I8: =I6+I7 -> -22100 | ... M8: =M6+M7 -> -20100 | N8: =SUM(B8:M8) -> -248200 | O8: =SUMIF(RawData!A:A,"=2024",RawData!E:E)-SUMIF(RawData!A:A,"=2024",RawData!J:J)+SUMIF(RawData!A:A,"=2024",RawData!D:D)-SUMIF(RawData!A:A,"=2024",RawData!I:I) -> -248200 | P8: =O8/(SUMIF(RawData!A:A,"=2024",RawData!J:J)+SUMIF(RawData!A:A,"=2024",RawData!I:I)) -> -0.085941828 | Q8: "Shortfall total de €248,700. Variância idêntica em % nas duas linhas elimina mix como causa — problema de volume ou preço."
A11: Costs
A12: Personnel | B12: =RawData!K26-RawData!F26 -> 9700 | C12: =RawData!K27-RawData!F27 -> 10500 | D12: =RawData!K28-RawData!F28 -> 12200 | E12: =RawData!K29-RawData!F29 -> 14600 | F12: =RawData!K30-RawData!F30 -> 15500 | G12: =RawData!K31-RawData!F31 -> 15500 | H12: =RawData!K32-RawData!F32 -> 15500 | I12: =RawData!K33-RawData!F33 -> 14600 | J12: =RawData!K34-RawData!F34 -> 13800 | K12: =RawData!K35-RawData!F35 -> 13800 | L12: =RawData!K36-RawData!F36 -> 13000 | M12: =RawData!K37-RawData!F37 -> 13000 | N12: =SUM(B12:M12) -> 161700 | O12: =SUMIF(RawData!A:A,"=2024",RawData!K:K)-SUMIF(RawData!A:A,"=2024",RawData!F:F) -> 161700 | P12: =IF(SUMIF(RawData!A:A,"=2024",RawData!K:K)=0,0,O12/SUMIF(RawData!A:A,"=2024",RawData!K:K)) -> 0.086217009 | Q12: "Custos abaixo do budget em 8.6% — proporcional ao shortfall de receita. Não é poupança real: reflecte headcount abaixo do plano que causou simultaneamente menos receita e menos custo."
A13: Operations | B13: =RawData!L26-RawData!G26 -> 1200 | C13: =RawData!L27-RawData!G27 -> 1300 | D13: =RawData!L28-RawData!G28 -> 1500 | E13: =RawData!L29-RawData!G29 -> 1800 | F13: =RawData!L30-RawData!G30 -> 1900 | G13: =RawData!L31-RawData!G31 -> 1900 | H13: =RawData!L32-RawData!G32 -> 1900 | I13: =RawData!L33-RawData!G33 -> 1800 | J13: =RawData!L34-RawData!G34 -> 1700 | K13: =RawData!L35-RawData!G35 -> 1700 | L13: =RawData!L36-RawData!G36 -> 1600 | M13: =RawData!L37-RawData!G37 -> 1600 | N13: =SUM(B13:M13) -> 19900 | O13: =SUMIF(RawData!A:A,"=2024",RawData!L:L)-SUMIF(RawData!A:A,"=2024",RawData!G:G) -> 19900 | P13: =IF(SUMIF(RawData!A:A,"=2024",RawData!L:L)=0,0,O13/SUMIF(RawData!A:A,"=2024",RawData!L:L)) -> 0.086221837 | Q13: "Abaixo do budget em 8.6% — custos variáveis que escalaram com a actividade. Comportamento esperado e proporcional."
A14: Other | B14: =RawData!M26-RawData!H26 -> 600 | C14: =RawData!M27-RawData!H27 -> 600 | D14: =RawData!M28-RawData!H28 -> 700 | E14: =RawData!M29-RawData!H29 -> 900 | F14: =RawData!M30-RawData!H30 -> 900 | G14: =RawData!M31-RawData!H31 -> 900 | H14: =RawData!M32-RawData!H32 -> 900 | I14: =RawData!M33-RawData!H33 -> 900 | J14: =RawData!M34-RawData!H34 -> 900 | K14: =RawData!M35-RawData!H35 -> 900 | L14: =RawData!M36-RawData!H36 -> 800 | M14: =RawData!M37-RawData!H37 -> 800 | N14: =SUM(B14:M14) -> 9800 | O14: =SUMIF(RawData!A:A,"=2024",RawData!M:M)-SUMIF(RawData!A:A,"=2024",RawData!H:H) -> 9800 | P14: =IF(SUMIF(RawData!A:A,"=2024",RawData!M:M)=0,0,O14/SUMIF(RawData!A:A,"=2024",RawData!M:M)) -> 0.08492201 | Q14: "Abaixo do budget em 8.5% — ligeiramente menos proporcional, sugerindo pequena componente fixa."
A15: Total Costs | B15: =B13+B14+B12 -> 11500 | C15: =C13+C14+C12 -> 12400 | D15: =D13+D14+D12 -> 14400 | E15: =E13+E14+E12 -> 17300 | F15: =F13+F14+F12 -> 18300 | G15: =G13+G14+G12 -> 18300 | H15: =H13+H14+H12 -> 18300 | I15: =I13+I14+I12 -> 17300 | ... M15: =M13+M14+M12 -> 15400 | N15: =SUM(B15:M15) -> 191400 | O15: =SUMIF(RawData!A:A,"=2024",RawData!K:K)-SUMIF(RawData!A:A,"=2024",RawData!F:F)+SUMIF(RawData!A:A,"=2024",RawData!L:L)-SUMIF(RawData!A:A,"=2024",RawData!G:G)+SUMIF(RawData!A:A,"=2024",RawData!M:M)-SUMIF(RawData!A:A,"=2024",RawData!H:H) -> 191400 | P15: =O15/(SUMIF(RawData!A:A,"=2024",RawData!K:K)+SUMIF(RawData!A:A,"=2024",RawData!L:L)+SUMIF(RawData!A:A,"=2024",RawData!M:M)) -> 0.086150245
A17: EBITDA | B17: =(RawData!D26+RawData!E26-RawData!F26-RawData!G26-RawData!H26)-(RawData!I26+RawData!J26-RawData!K26-RawData!L26-RawData!M26) -> -4600 | C17: =(RawData!D27+RawData!E27-RawData!F27-RawData!G27-RawData!H27)-(RawData!I27+RawData!J27-RawData!K27-RawData!L27-RawData!M27) -> -4700 | D17: =(RawData!D28+RawData!E28-RawData!F28-RawData!G28-RawData!H28)-(RawData!I28+RawData!J28-RawData!K28-RawData!L28-RawData!M28) -> -4700 | E17: =(RawData!D29 + RawData!E29 - RawData!F29 - RawData!G29 - RawData!H29) - (RawData!I29 + RawData!J29 - RawData!K29 - RawData!L29 - RawData!M29) -> -4800 | F17: =(RawData!D30 + RawData!E30 - RawData!F30 - RawData!G30 - RawData!H30) - (RawData!I30 + RawData!J30 - RawData!K30 - RawData!L30 - RawData!M30) -> -4800 | G17: =(RawData!D31 + RawData!E31 - RawData!F31 - RawData!G31 - RawData!H31) - (RawData!I31 + RawData!J31 - RawData!K31 - RawData!L31 - RawData!M31) -> -4800 | H17: =(RawData!D32 + RawData!E32 - RawData!F32 - RawData!G32 - RawData!H32) - (RawData!I32 + RawData!J32 - RawData!K32 - RawData!L32 - RawData!M32) -> -4800 | I17: =(RawData!D33 + RawData!E33 - RawData!F33 - RawData!G33 - RawData!H33) - (RawData!I33 + RawData!J33 - RawData!K33 - RawData!L33 - RawData!M33) -> -4800 | J17: =(RawData!D34 + RawData!E34 - RawData!F34 - RawData!G34 - RawData!H34) - (RawData!I34 + RawData!J34 - RawData!K34 - RawData!L34 - RawData!M34) -> -4700 | K17: =(RawData!D35 + RawData!E35 - RawData!F35 - RawData!G35 - RawData!H35) - (RawData!I35 + RawData!J35 - RawData!K35 - RawData!L35 - RawData!M35) -> -4700 | L17: =(RawData!D36 + RawData!E36 - RawData!F36 - RawData!G36 - RawData!H36) - (RawData!I36 + RawData!J36 - RawData!K36 - RawData!L36 - RawData!M36) -> -4700 | M17: =(RawData!D37 + RawData!E37 - RawData!F37 - RawData!G37 - RawData!H37) - (RawData!I37 + RawData!J37 - RawData!K37 - RawData!L37 - RawData!M37) -> -4700 | N17: =SUM(B17:M17) -> -56800 | O17: =O8+O15 -> -56800 | P17: =O17/(SUMIF(RawData!A:A,"=2024",RawData!I:I)+SUMIF(RawData!A:A,"=2024",RawData!J:J)-SUMIF(RawData!A:A,"=2024",RawData!L:L)-SUMIF(RawData!A:A,"=2024",RawData!M:M)-SUMIF(RawData!A:A,"=2024",RawData!K:K)) -> -0.085246886 | Q17: "EBITDA abaixo em valor absoluto- O problema é de volume — a empresa foi eficiente mas não gerou actividade suficiente para atingir o budget."
A18: EBITDA Margin % | B18: =IF((RawData!D26+RawData!E26)=0,0,(RawData!D26+RawData!E26-RawData!F26-RawData!G26-RawData!H26)/(RawData!D26+RawData!E26))-IF((RawData!I26+RawData!J26)=0,0,(RawData!I26+RawData!J26-RawData!K26-RawData!L26-RawData!M26)/(RawData!I26+RawData!J26)) -> -3.5783742e-05 | C18: =IF((RawData!D27+RawData!E27)=0,0,(RawData!D27+RawData!E27-RawData!F27-RawData!G27-RawData!H27)/(RawData!D27+RawData!E27)) - IF((RawData!I27+RawData!J27)=0,0,(RawData!I27+RawData!J27-RawData!K27-RawData!L27-RawData!M27)/(RawData!I27+RawData!J27)) -> -0.00034137134 | D18: =IF((RawData!D28+RawData!E28)=0,0,(RawData!D28+RawData!E28-RawData!F28-RawData!G28-RawData!H28)/(RawData!D28+RawData!E28)) - IF((RawData!I28+RawData!J28)=0,0,(RawData!I28+RawData!J28-RawData!K28-RawData!L28-RawData!M28)/(RawData!I28+RawData!J28)) -> 4.1397912e-05 | E18: =IF((RawData!D29+RawData!E29)=0,0,(RawData!D29+RawData!E29-RawData!F29-RawData!G29-RawData!H29)/(RawData!D29+RawData!E29)) - IF((RawData!I29+RawData!J29)=0,0,(RawData!I29+RawData!J29-RawData!K29-RawData!L29-RawData!M29)/(RawData!I29+RawData!J29)) -> 0.0001314167 | F18: =IF((RawData!D30+RawData!E30)=0,0,(RawData!D30+RawData!E30-RawData!F30-RawData!G30-RawData!H30)/(RawData!D30+RawData!E30)) - IF((RawData!I30+RawData!J30)=0,0,(RawData!I30+RawData!J30-RawData!K30-RawData!L30-RawData!M30)/(RawData!I30+RawData!J30)) -> 0.0002682114 | G18: =IF((RawData!D31+RawData!E31)=0,0,(RawData!D31+RawData!E31-RawData!F31-RawData!G31-RawData!H31)/(RawData!D31+RawData!E31)) - IF((RawData!I31+RawData!J31)=0,0,(RawData!I31+RawData!J31-RawData!K31-RawData!L31-RawData!M31)/(RawData!I31+RawData!J31)) -> 0.0002682114 | H18: =IF((RawData!D32+RawData!E32)=0,0,(RawData!D32+RawData!E32-RawData!F32-RawData!G32-RawData!H32)/(RawData!D32+RawData!E32)) - IF((RawData!I32+RawData!J32)=0,0,(RawData!I32+RawData!J32-RawData!K32-RawData!L32-RawData!M32)/(RawData!I32+RawData!J32)) -> 0.0002682114 | I18: =IF((RawData!D33+RawData!E33)=0,0,(RawData!D33+RawData!E33-RawData!F33-RawData!G33-RawData!H33)/(RawData!D33+RawData!E33)) - IF((RawData!I33+RawData!J33)=0,0,(RawData!I33+RawData!J33-RawData!K33-RawData!L33-RawData!M33)/(RawData!I33+RawData!J33)) -> 0.0001314167 | J18: =IF((RawData!D34+RawData!E34)=0,0,(RawData!D34+RawData!E34-RawData!F34-RawData!G34-RawData!H34)/(RawData!D34+RawData!E34)) - IF((RawData!I34+RawData!J34)=0,0,(RawData!I34+RawData!J34-RawData!K34-RawData!L34-RawData!M34)/(RawData!I34+RawData!J34)) -> 0.00038881689 | K18: =IF((RawData!D35+RawData!E35)=0,0,(RawData!D35+RawData!E35-RawData!F35-RawData!G35-RawData!H35)/(RawData!D35+RawData!E35)) - IF((RawData!I35+RawData!J35)=0,0,(RawData!I35+RawData!J35-RawData!K35-RawData!L35-RawData!M35)/(RawData!I35+RawData!J35)) -> 0.00038881689 | L18: =IF((RawData!D36+RawData!E36)=0,0,(RawData!D36+RawData!E36-RawData!F36-RawData!G36-RawData!H36)/(RawData!D36+RawData!E36)) - IF((RawData!I36+RawData!J36)=0,0,(RawData!I36+RawData!J36-RawData!K36-RawData!L36-RawData!M36)/(RawData!I36+RawData!J36)) -> 0.00020376813 | M18: =IF((RawData!D37+RawData!E37)=0,0,(RawData!D37+RawData!E37-RawData!F37-RawData!G37-RawData!H37)/(RawData!D37+RawData!E37)) - IF((RawData!I37+RawData!J37)=0,0,(RawData!I37+RawData!J37-RawData!K37-RawData!L37-RawData!M37)/(RawData!I37+RawData!J37)) -> 0.00020376813 | N18: =(SUMIF(RawData!A:A,2024,RawData!D:D)+SUMIF(RawData!A:A,2024,RawData!E:E)-SUMIF(RawData!A:A,2024,RawData!F:F)-SUMIF(RawData!A:A,2024,RawData!G:G)-SUMIF(RawData!A:A,2024,RawData!H:H))/(SUMIF(RawData!A:A,2024,RawData!D:D)+SUMIF(RawData!A:A,2024,RawData!E:E))-((SUMIF(RawData!A:A,2024,RawData!I:I)+SUMIF(RawData!A:A,2024,RawData!J:J)-SUMIF(RawData!A:A,2024,RawData!K:K)-SUMIF(RawData!A:A,2024,RawData!L:L)-SUMIF(RawData!A:A,2024,RawData!M:M))/(SUMIF(RawData!A:A,2024,RawData!I:I)+SUMIF(RawData!A:A,2024,RawData!J:J))) -> 0.00017540729
A19: Check | B19: =B17-B15-B8 -> 0 | C19: =C17-C15-C8 -> 0 | D19: =D17-D15-D8 -> 0 | E19: =E17-E15-E8 -> 0 | F19: =F17-F15-F8 -> 0 | G19: =G17-G15-G8 -> 0 | H19: =H17-H15-H8 -> 0 | I19: =I17-I15-I8 -> 0 | ... O19: =O17-O15-O8 -> 0 | R19: +
Q20: 0;
Q21: (
A22: Month | B22: Actual Revenue 2024 | C22: Budget Revenue 2025 | D22: Variance €
A23: jan | B23: =RawData!D26+RawData!E26 -> 171400 | C23: =RawData!I26+RawData!J26 -> 187500 | D23: =C23-B23 -> 16100
A24: fev | B24: =RawData!D27+RawData!E27 -> 182000 | C24: =RawData!I27+RawData!J27 -> 199100 | D24: =C24-B24 -> 17100
A25: mar | B25: =RawData!D28+RawData!E28 -> 203200 | C25: =RawData!I28+RawData!J28 -> 222300 | D25: =C25-B25 -> 19100
A26: abr | B26: =RawData!D29+RawData!E29 -> 235000 | C26: =RawData!I29+RawData!J29 -> 257100 | D26: =C26-B26 -> 22100
A27: mai | B27: =RawData!D30+RawData!E30 -> 245600 | C27: =RawData!I30+RawData!J30 -> 268700 | D27: =C27-B27 -> 23100
A28: jun | B28: =RawData!D31+RawData!E31 -> 245600 | C28: =RawData!I31+RawData!J31 -> 268700 | D28: =C28-B28 -> 23100
A29: jul | B29: =RawData!D32+RawData!E32 -> 245600 | C29: =RawData!I32+RawData!J32 -> 268700 | D29: =C29-B29 -> 23100
A30: ago | B30: =RawData!D33+RawData!E33 -> 235000 | C30: =RawData!I33+RawData!J33 -> 257100 | D30: =C30-B30 -> 22100
A31: set | B31: =RawData!D34+RawData!E34 -> 224400 | C31: =RawData!I34+RawData!J34 -> 245500 | D31: =C31-B31 -> 21100
A32: out | B32: =RawData!D35+RawData!E35 -> 224400 | C32: =RawData!I35+RawData!J35 -> 245500 | D32: =C32-B32 -> 21100 | Q32: )
A33: nov | B33: =RawData!D36+RawData!E36 -> 213800 | C33: =RawData!I36+RawData!J36 -> 233900 | D33: =C33-B33 -> 20100 | Q33: /
A34: dez | B34: =RawData!D37+RawData!E37 -> 213800 | C34: =RawData!I37+RawData!J37 -> 233900 | D34: =C34-B34 -> 20100 | Q34: (
A36: Month | B36: Actual Cost 2024 | C36: Budget Cost 2025 | D36: Variance €
A37: jan | B37: =RawData!F26+RawData!G26+RawData!H26 -> 122500 | C37: =RawData!K26+RawData!L26+RawData!M26 -> 134000 | D37: =C37-B37 -> 11500 | Q37: )
A38: fev | B38: =RawData!F27+RawData!G27+RawData!H27 -> 132700 | C38: =RawData!K27+RawData!L27+RawData!M27 -> 145100 | D38: =C38-B38 -> 12400 | Q38: -
A39: mar | B39: =RawData!F28+RawData!G28+RawData!H28 -> 153100 | C39: =RawData!K28+RawData!L28+RawData!M28 -> 167500 | D39: =C39-B39 -> 14400 | Q39: (
A40: abr | B40: =RawData!F29+RawData!G29+RawData!H29 -> 183600 | C40: =RawData!K29+RawData!L29+RawData!M29 -> 200900 | D40: =C40-B40 -> 17300
A41: mai | B41: =RawData!F30+RawData!G30+RawData!H30 -> 193800 | C41: =RawData!K30+RawData!L30+RawData!M30 -> 212100 | D41: =C41-B41 -> 18300
A42: jun | B42: =RawData!F31+RawData!G31+RawData!H31 -> 193800 | C42: =RawData!K31+RawData!L31+RawData!M31 -> 212100 | D42: =C42-B42 -> 18300
A43: jul | B43: =RawData!F32+RawData!G32+RawData!H32 -> 193800 | C43: =RawData!K32+RawData!L32+RawData!M32 -> 212100 | D43: =C43-B43 -> 18300
A44: ago | B44: =RawData!F33+RawData!G33+RawData!H33 -> 183600 | C44: =RawData!K33+RawData!L33+RawData!M33 -> 200900 | D44: =C44-B44 -> 17300
A45: set | B45: =RawData!F34+RawData!G34+RawData!H34 -> 173400 | C45: =RawData!K34+RawData!L34+RawData!M34 -> 189800 | D45: =C45-B45 -> 16400
...

Sheet P&L
A1: NovaTech Consulting Lda. — Profit & Loss Statement
A4: Row Label | B4: Jan | C4: Feb | D4: Mar | E4: Apr | F4: May | G4: Jun | H4: Jul | I4: Aug | J4: Sep | K4: Oct | L4: Nov | M4: Dec | N4: TOTAL | O4: % of Revenue
A5: Consulting Fees | B5: =Drivers!B8*Drivers!B14 -> 234600 | C5: =Drivers!C8*Drivers!C14 -> 234600 | D5: =Drivers!D8*Drivers!D14 -> 234600 | E5: =Drivers!E8*Drivers!E14 -> 239200 | F5: =Drivers!F8*Drivers!F14 -> 239200 | G5: =Drivers!G8*Drivers!G14 -> 239200 | H5: =Drivers!H8*Drivers!H14 -> 239200 | I5: =Drivers!I8*Drivers!I14 -> 239200 | ... M5: =Drivers!M8*Drivers!M14 -> 243800 | N5: =SUM(B5:M5) -> 2870400 | O5: =IF(N7=0,0,N5/N7) -> 0.8440367
A6: Managed Services | B6: =Drivers!B19 -> 44200 | C6: =Drivers!C19 -> 44200 | D6: =Drivers!D19 -> 44200 | E6: =Drivers!E19 -> 44200 | F6: =Drivers!F19 -> 44200 | G6: =Drivers!G19 -> 44200 | H6: =Drivers!H19 -> 44200 | I6: =Drivers!I19 -> 44200 | ... M6: =Drivers!M19 -> 44200 | N6: =SUM(B6:M6) -> 530400 | O6: =IF(N7=0,0,N6/N7) -> 0.1559633
A7: Total Revenue | B7: =B5+B6 -> 278800 | C7: =C5+C6 -> 278800 | D7: =D5+D6 -> 278800 | E7: =E5+E6 -> 283400 | F7: =F5+F6 -> 283400 | G7: =G5+G6 -> 283400 | H7: =H5+H6 -> 283400 | I7: =I5+I6 -> 283400 | ... M7: =M5+M6 -> 288000 | N7: =SUM(B7:M7) -> 3400800 | O7: =IF(N7=0,0,N7/N7) -> 1
A9: Personnel | B9: =Drivers!B8*Drivers!E25 -> 140070.19 | C9: =Drivers!C8*Drivers!E25 -> 140070.19 | D9: =Drivers!D8*Drivers!E25 -> 140070.19 | E9: =Drivers!E8*Drivers!E25 -> 142816.67 | F9: =Drivers!F8*Drivers!E25 -> 142816.67 | G9: =Drivers!G8*Drivers!E25 -> 142816.67 | H9: =Drivers!H8*Drivers!E25 -> 142816.67 | I9: =Drivers!I8*Drivers!E25 -> 142816.67 | J9: =Drivers!J8*Drivers!E25 -> 142816.67 | K9: =Drivers!K8*Drivers!E25 -> 145563.14 | L9: =Drivers!L8*Drivers!E25 -> 145563.14 | M9: =Drivers!M8*Drivers!E25 -> 145563.14 | N9: =SUM(B9:M9) -> 1713800 | O9: =IF(N7=0,0,N9/N7) -> 0.50394025
A10: Operations | B10: =RawData!G26 -> 12700 | C10: =RawData!G27 -> 13800 | D10: =RawData!G28 -> 15900 | E10: =RawData!G29 -> 19100 | F10: =RawData!G30 -> 20100 | G10: =RawData!G31 -> 20100 | H10: =RawData!G32 -> 20100 | I10: =RawData!G33 -> 19100 | J10: =RawData!G34 -> 18000 | K10: =RawData!G35 -> 18000 | L10: =RawData!G36 -> 17000 | M10: =RawData!G37 -> 17000 | N10: =SUM(B10:M10) -> 210900 | O10: =IF(N7=0,0,N10/N7) -> 0.06201482
A11: Other | B11: =RawData!H26 -> 6400 | C11: =RawData!H27 -> 6900 | D11: =RawData!H28 -> 8000 | E11: =RawData!H29 -> 9500 | F11: =RawData!H30 -> 10100 | G11: =RawData!H31 -> 10100 | H11: =RawData!H32 -> 10100 | I11: =RawData!H33 -> 9500 | J11: =RawData!H34 -> 9000 | K11: =RawData!H35 -> 9000 | L11: =RawData!H36 -> 8500 | M11: =RawData!H37 -> 8500 | N11: =SUM(B11:M11) -> 105600 | O11: =IF(N7=0,0,N11/N7) -> 0.031051517
A12: Total Costs | B12: =B9+B10+B11 -> 159170.19 | C12: =C9+C10+C11 -> 160770.19 | D12: =D9+D10+D11 -> 163970.19 | E12: =E9+E10+E11 -> 171416.67 | F12: =F9+F10+F11 -> 173016.67 | G12: =G9+G10+G11 -> 173016.67 | H12: =H9+H10+H11 -> 173016.67 | I12: =I9+I10+I11 -> 171416.67 | ... M12: =M9+M10+M11 -> 171063.14 | N12: =SUM(B12:M12) -> 2030300 | O12: =IF(N7=0,0,N12/N7) -> 0.59700659
A14: GROSS PROFIT | B14: =B7-B12 -> 119629.81 | C14: =C7-C12 -> 118029.81 | D14: =D7-D12 -> 114829.81 | E14: =E7-E12 -> 111983.33 | F14: =F7-F12 -> 110383.33 | G14: =G7-G12 -> 110383.33 | H14: =H7-H12 -> 110383.33 | I14: =I7-I12 -> 111983.33 | ... M14: =M7-M12 -> 116936.86 | N14: =SUM(B14:M14) -> 1370500 | O14: =IF(N7=0,0,N14/N7) -> 0.40299341
A15: EBITDA | B15: =B14 -> 119629.81 | C15: =C14 -> 118029.81 | D15: =D14 -> 114829.81 | E15: =E14 -> 111983.33 | F15: =F14 -> 110383.33 | G15: =G14 -> 110383.33 | H15: =H14 -> 110383.33 | I15: =I14 -> 111983.33 | ... M15: =M14 -> 116936.86 | N15: =SUM(B15:M15) -> 1370500 | O15: =IF(N7=0,0,N15/N7) -> 0.40299341
A16: EBITDA Margin % | B16: =IF(B7=0,0,B15/B7) -> 0.42908826 | C16: =IF(C7=0,0,C15/C7) -> 0.42334938 | D16: =IF(D7=0,0,D15/D7) -> 0.41187162 | E16: =IF(E7=0,0,E15/E7) -> 0.39514232 | F16: =IF(F7=0,0,F15/F7) -> 0.38949659 | G16: =IF(G7=0,0,G15/G7) -> 0.38949659 | H16: =IF(H7=0,0,H15/H7) -> 0.38949659 | I16: =IF(I7=0,0,I15/I7) -> 0.39514232 | ... N16: =IF(N7=0,0,N15/N7) -> 0.40299341
A18: D&A (2% rev) | B18: =0.02*B7 -> 5576 | C18: =0.02*C7 -> 5576 | D18: =0.02*D7 -> 5576 | E18: =0.02*E7 -> 5668 | F18: =0.02*F7 -> 5668 | G18: =0.02*G7 -> 5668 | H18: =0.02*H7 -> 5668 | I18: =0.02*I7 -> 5668 | ... M18: =0.02*M7 -> 5760 | N18: =SUM(B18:M18) -> 68016 | O18: =IF(N7=0,0,N18/N7) -> 0.02
A19: EBIT | B19: =B15-B18 -> 114053.81 | C19: =C15-C18 -> 112453.81 | D19: =D15-D18 -> 109253.81 | E19: =E15-E18 -> 106315.33 | F19: =F15-F18 -> 104715.33 | G19: =G15-G18 -> 104715.33 | H19: =H15-H18 -> 104715.33 | I19: =I15-I18 -> 106315.33 | ... M19: =M15-M18 -> 111176.86 | N19: =SUM(B19:M19) -> 1302484 | O19: =IF(N7=0,0,N19/N7) -> 0.38299341
A20: Tax (21%) | B20: =IF(B19>0,B19*0.21,0) -> 23951.3 | C20: =IF(C19>0,C19*0.21,0) -> 23615.3 | D20: =IF(D19>0,D19*0.21,0) -> 22943.3 | E20: =IF(E19>0,E19*0.21,0) -> 22326.22 | F20: =IF(F19>0,F19*0.21,0) -> 21990.22 | G20: =IF(G19>0,G19*0.21,0) -> 21990.22 | H20: =IF(H19>0,H19*0.21,0) -> 21990.22 | I20: =IF(I19>0,I19*0.21,0) -> 22326.22 | ... M20: =IF(M19>0,M19*0.21,0) -> 23347.14 | N20: =SUM(B20:M20) -> 273521.64 | O20: =IF(N7=0,0,N20/N7) -> 0.080428617
A21: NET INCOME | B21: =B19-B20 -> 90102.508 | C21: =C19-C20 -> 88838.508 | D21: =D19-D20 -> 86310.508 | E21: =E19-E20 -> 83989.113 | F21: =F19-F20 -> 82725.113 | G21: =G19-G20 -> 82725.113 | H21: =H19-H20 -> 82725.113 | I21: =I19-I20 -> 83989.113 | ... M21: =M19-M20 -> 87829.719 | N21: =SUM(B21:M21) -> 1028962.4 | O21: =IF(N21=0,0,N21/N7) -> 0.3025648

Sheet Dashboard
B2: Dashboard — to be built in Week 5 (Power BI)

Sheet _Info
B2: NovaTech Consulting Lda. — Modelo FP&A
B4: FICHEIRO FICTÍCIO para prática de FP&A
B6: ESTRUTURA:
B7: RawData → Dados históricos mensais 2022-2024 + Budget 2025
B8: P&L → Estrutura do P&L (fórmulas a construir na Semana 2)
B9: Dashboard → Vazio (Power BI na Semana 5)
B11: CONVENÇÕES DE CORES:
B12: Texto azul → Inputs hardcoded (números que podes alterar)
B13: Texto preto → Fórmulas calculadas
B14: Texto verde → Links de outras sheets
B16: EMPRESA:
B17: Consultora de IT e gestão, Lisboa
... B19: Sazonalidade: Q1 fraco (~20%), Q2-Q3 forte (~55%), Q4 médio (~25%)

Sheet Assumptions
B2: Model Assumptions — NovaTech Consulting Lda.
B3: Assumption | D3: Value | E3: Source / Notes
B4: SEASONALITY
B5: MS revenue is FLAT (recurring contracts ÷12). Consulting revenue is seasonal. This is intentional and realistic.
B6: January weight | D6: 6.0% | E6: Estimate based on typical IT consultancy pattern — Q1 slow start
B7: February weight | D7: 6.5% | E7: Estimate — gradually increasing
B8: March weight | D8: 7.5% | E8: Estimate — end of Q1 pickup
B9: April–June weight | D9: ~9.0-9.5% each | E9: Estimate — Q2 peak activity
B10: July–September weight | D10: ~8.5-9.5% each | E10: Estimate — Q3 strong, slight Aug dip
B11: October–December weight | D11: ~8.0-8.5% each | E11: Estimate — Q4 moderate
B12: Source | D12: Internal estimate | E12: ⚠ To be recalculated from historical data in Week 4 forecasting model
B14: FINANCIAL ASSUMPTIONS
B15: D&A rate | D15: 2% of Revenue | E15: Assumption — low asset base for consultancy
B16: IRC Tax rate | D16: 21% | E16: Portugal corporate tax rate 2024
B17: Personnel as % Rev | D17: ~65% | E17: Derived from historical data 2022-2024
B18: Operations as % Rev | D18: ~8% | E18: Derived from historical data
B20: VARIANCE CONVENTION
B21: Revenue variance | D21: Actual - Budget | E21: Positive = outperformed budget (good)
B22: Cost variance | D22: Budget - Actual | E22: Positive = under budget (good)
B23: EBITDA variance | D23: Actual - Budget | E23: Positive = better than planned (good)
B25: MODEL VERSION
B26: Version | D26: Week 2 target | E26: Variance Analysis complete — Forecasting in Week 4
B27: Last updated | D27: June 2025
B28: Author | D28: Daniela Marques
